
Exception in thread Thread-1:
Traceback (most recent call last):
  File "/Users/user/anaconda3/envs/parser_avito-master/lib/python3.8/site-packages/seleniumbase/core/browser_launcher.py", line 3074, in get_local_driver
    driver = undetected.Chrome(
  File "/Users/user/anaconda3/envs/parser_avito-master/lib/python3.8/site-packages/seleniumbase/undetected/__init__.py", line 277, in __init__
    browser = subprocess.Popen(
  File "/Users/user/anaconda3/envs/parser_avito-master/lib/python3.8/subprocess.py", line 858, in __init__
    self._execute_child(args, executable, preexec_fn, close_fds,
  File "/Users/user/anaconda3/envs/parser_avito-master/lib/python3.8/subprocess.py", line 1601, in _execute_child
    and os.path.dirname(executable)
  File "/Users/user/anaconda3/envs/parser_avito-master/lib/python3.8/posixpath.py", line 152, in dirname
    p = os.fspath(p)
TypeError: expected str, bytes or os.PathLike object, not NoneType

During handling of the above exception, another exception occurred:

Traceback (most recent call last):
  File "/Users/user/anaconda3/envs/parser_avito-master/lib/python3.8/threading.py", line 932, in _bootstrap_inner
    self.run()
  File "/Users/user/anaconda3/envs/parser_avito-master/lib/python3.8/threading.py", line 870, in run
    self._target(*self._args, **self._kwargs)
  File "/Users/user/Yandex.Disk-a.mironov.intmar@immag.ru.localized/parser_avito-master/AvitoParser.py", line 174, in start_scraping
    self.run_parse()
  File "/Users/user/Yandex.Disk-a.mironov.intmar@immag.ru.localized/parser_avito-master/AvitoParser.py", line 288, in run_parse
    AvitoParse(
  File "/Users/user/Yandex.Disk-a.mironov.intmar@immag.ru.localized/parser_avito-master/parser_cls.py", line 296, in parse
    with SB(uc=True,
  File "/Users/user/anaconda3/envs/parser_avito-master/lib/python3.8/contextlib.py", line 113, in __enter__
    return next(self.gen)
  File "/Users/user/anaconda3/envs/parser_avito-master/lib/python3.8/site-packages/seleniumbase/plugins/sb_manager.py", line 815, in SB
    sb.setUp()
  File "/Users/user/anaconda3/envs/parser_avito-master/lib/python3.8/site-packages/seleniumbase/fixtures/base_case.py", line 13915, in setUp
    self.driver = self.get_new_driver(
  File "/Users/user/anaconda3/envs/parser_avito-master/lib/python3.8/site-packages/seleniumbase/fixtures/base_case.py", line 3818, in get_new_driver
    new_driver = browser_launcher.get_driver(
  File "/Users/user/anaconda3/envs/parser_avito-master/lib/python3.8/site-packages/seleniumbase/core/browser_launcher.py", line 1261, in get_driver
    return get_local_driver(
  File "/Users/user/anaconda3/envs/parser_avito-master/lib/python3.8/site-packages/seleniumbase/core/browser_launcher.py", line 3385, in get_local_driver
    return webdriver.Chrome()
  File "/Users/user/anaconda3/envs/parser_avito-master/lib/python3.8/site-packages/selenium/webdriver/chrome/webdriver.py", line 49, in __init__
    super().__init__(
  File "/Users/user/anaconda3/envs/parser_avito-master/lib/python3.8/site-packages/selenium/webdriver/chromium/webdriver.py", line 54, in __init__
onse
    raise exception_class(message, screen, stacktrace)
selenium.common.exceptions.WebDriverException: Message: unknown error: cannot find Chrome binary
Stacktrace:
0   chromedriver                        0x00000001013c26b8 chromedriver